Workbook

Sheet DASHBOARD
B2: ALGOPICK — COMPARADOR DE FORECAST
B3: Todas las alternativas de forecast por intersección EAN–CFG, y simulación del consensus al cambiar el System FC.
B5: EAN | C5: 3614229382112 | D5: ← escribe aquí el EAN | F5: Descripción | G5: =_CALC!$F$23
B6: CFG a graficar | C6: (TODOS) | D6: ← "(TODOS)" = combinado | F6: House / Brand | G6: =_CALC!$F$20&" / "&_CALC!$F$21
B7: Versión actual | C7: CurrentWorkingView | D7: ← versión de trabajo | F7: Product Line | G7: =_CALC!$F$22
B8: Versión snapshot | C8: =_CALC!$F$16 | D8: ← auto; puedes sobrescribir | F8: Estado | G8: =IF(_CALC!$F$14=0,"EAN NO ENCONTRADO en CONSENSUS","OK · "&_CALC!$F$14&" filas · "&_CALC!$B$9&" CFG · "&_CALC!$B$8&" meses")
B9: Primer mes futuro | C9: =_CALC!$F$17 | D9: ← auto (snapshot + 1 mes) | F9: Meses del eje X | G9: =IF(_CALC!$B$8=0,"—",_CALC!$D$26&" → "&INDEX(_CALC!$D$26:$AM$26,_CALC!$B$8))
B10: =IF(_CALC!$B$8<>12,"AVISO: los gráficos están dibujados sobre 12 meses y la cabecera trae ahora "&_CALC!$B$8&". Amplía el rango de las series de ambos gráficos (_CALC, filas 34-50 y 163-168).",IF(_CALC!$F$18>10,"AVISO: este EAN tiene "&_CALC!$F$18&" algoritmos activos y el gráfico 1 sólo dibuja 10. Añade series apuntando a _CALC filas 51 en adelante.",""))
B11: DATOS MAESTROS POR INTERSECCIÓN · pestaña ADHOC
B12: CFG | C12: Final Segment | D12: System Bestfit Algorithm | E12: Planner Bestfit Algorithm | F12: System Assigned Algorithm List | G12: Planner Additions | H12: System BestFit Final | I12: BestFit vigente (1er → últ. mes)
B13: =IF(_CALC!$B$113="","",_CALC!$B$113) | C13: =IF(_CALC!$C$113=0,"",IFERROR(INDEX(ADHOC!$A$2:$BZ$20001,_CALC!$C$113,MATCH("Final Segment",ADHOC!$1:$1,0)),"")) | D13: =IF(_CALC!$C$113=0,"",IFERROR(INDEX(ADHOC!$A$2:$BZ$20001,_CALC!$C$113,MATCH("System Bestfit Algorithm",ADHOC!$1:$1,0)),"")) | E13: =IF(_CALC!$C$113=0,"",IFERROR(INDEX(ADHOC!$A$2:$BZ$20001,_CALC!$C$113,MATCH("Planner Bestfit Algorithm",ADHOC!$1:$1,0)),"")) | F13: =IF(_CALC!$C$113=0,"",IFERROR(INDEX(ADHOC!$A$2:$BZ$20001,_CALC!$C$113,MATCH("System Assigned Algorithm List",ADHOC!$1:$1,0)),"")) | G13: =IF(_CALC!$C$113=0,"",IFERROR(INDEX(ADHOC!$A$2:$BZ$20001,_CALC!$C$113,MATCH("Planner Additions",ADHOC!$1:$1,0)),"")) | H13: =IF(_CALC!$C$113=0,"",IFERROR(INDEX(ADHOC!$A$2:$BZ$20001,_CALC!$C$113,MATCH("System BestFit Final",ADHOC!$1:$1,0)),"")) | I13: =IF(_CALC!$B$113="","",_CALC!$H$113)
B14: =IF(_CALC!$B$114="","",_CALC!$B$114) | C14: =IF(_CALC!$C$114=0,"",IFERROR(INDEX(ADHOC!$A$2:$BZ$20001,_CALC!$C$114,MATCH("Final Segment",ADHOC!$1:$1,0)),"")) | D14: =IF(_CALC!$C$114=0,"",IFERROR(INDEX(ADHOC!$A$2:$BZ$20001,_CALC!$C$114,MATCH("System Bestfit Algorithm",ADHOC!$1:$1,0)),"")) | E14: =IF(_CALC!$C$114=0,"",IFERROR(INDEX(ADHOC!$A$2:$BZ$20001,_CALC!$C$114,MATCH("Planner Bestfit Algorithm",ADHOC!$1:$1,0)),"")) | F14: =IF(_CALC!$C$114=0,"",IFERROR(INDEX(ADHOC!$A$2:$BZ$20001,_CALC!$C$114,MATCH("System Assigned Algorithm List",ADHOC!$1:$1,0)),"")) | G14: =IF(_CALC!$C$114=0,"",IFERROR(INDEX(ADHOC!$A$2:$BZ$20001,_CALC!$C$114,MATCH("Planner Additions",ADHOC!$1:$1,0)),"")) | H14: =IF(_CALC!$C$114=0,"",IFERROR(INDEX(ADHOC!$A$2:$BZ$20001,_CALC!$C$114,MATCH("System BestFit Final",ADHOC!$1:$1,0)),"")) | I14: =IF(_CALC!$B$114="","",_CALC!$H$114)
B15: =IF(_CALC!$B$115="","",_CALC!$B$115) | C15: =IF(_CALC!$C$115=0,"",IFERROR(INDEX(ADHOC!$A$2:$BZ$20001,_CALC!$C$115,MATCH("Final Segment",ADHOC!$1:$1,0)),"")) | D15: =IF(_CALC!$C$115=0,"",IFERROR(INDEX(ADHOC!$A$2:$BZ$20001,_CALC!$C$115,MATCH("System Bestfit Algorithm",ADHOC!$1:$1,0)),"")) | E15: =IF(_CALC!$C$115=0,"",IFERROR(INDEX(ADHOC!$A$2:$BZ$20001,_CALC!$C$115,MATCH("Planner Bestfit Algorithm",ADHOC!$1:$1,0)),"")) | F15: =IF(_CALC!$C$115=0,"",IFERROR(INDEX(ADHOC!$A$2:$BZ$20001,_CALC!$C$115,MATCH("System Assigned Algorithm List",ADHOC!$1:$1,0)),"")) | G15: =IF(_CALC!$C$115=0,"",IFERROR(INDEX(ADHOC!$A$2:$BZ$20001,_CALC!$C$115,MATCH("Planner Additions",ADHOC!$1:$1,0)),"")) | H15: =IF(_CALC!$C$115=0,"",IFERROR(INDEX(ADHOC!$A$2:$BZ$20001,_CALC!$C$115,MATCH("System BestFit Final",ADHOC!$1:$1,0)),"")) | I15: =IF(_CALC!$B$115="","",_CALC!$H$115)
B16: =IF(_CALC!$B$116="","",_CALC!$B$116) | C16: =IF(_CALC!$C$116=0,"",IFERROR(INDEX(ADHOC!$A$2:$BZ$20001,_CALC!$C$116,MATCH("Final Segment",ADHOC!$1:$1,0)),"")) | D16: =IF(_CALC!$C$116=0,"",IFERROR(INDEX(ADHOC!$A$2:$BZ$20001,_CALC!$C$116,MATCH("System Bestfit Algorithm",ADHOC!$1:$1,0)),"")) | E16: =IF(_CALC!$C$116=0,"",IFERROR(INDEX(ADHOC!$A$2:$BZ$20001,_CALC!$C$116,MATCH("Planner Bestfit Algorithm",ADHOC!$1:$1,0)),"")) | F16: =IF(_CALC!$C$116=0,"",IFERROR(INDEX(ADHOC!$A$2:$BZ$20001,_CALC!$C$116,MATCH("System Assigned Algorithm List",ADHOC!$1:$1,0)),"")) | G16: =IF(_CALC!$C$116=0,"",IFERROR(INDEX(ADHOC!$A$2:$BZ$20001,_CALC!$C$116,MATCH("Planner Additions",ADHOC!$1:$1,0)),"")) | H16: =IF(_CALC!$C$116=0,"",IFERROR(INDEX(ADHOC!$A$2:$BZ$20001,_CALC!$C$116,MATCH("System BestFit Final",ADHOC!$1:$1,0)),"")) | I16: =IF(_CALC!$B$116="","",_CALC!$H$116)
B17: =IF(_CALC!$B$117="","",_CALC!$B$117) | C17: =IF(_CALC!$C$117=0,"",IFERROR(INDEX(ADHOC!$A$2:$BZ$20001,_CALC!$C$117,MATCH("Final Segment",ADHOC!$1:$1,0)),"")) | D17: =IF(_CALC!$C$117=0,"",IFERROR(INDEX(ADHOC!$A$2:$BZ$20001,_CALC!$C$117,MATCH("System Bestfit Algorithm",ADHOC!$1:$1,0)),"")) | E17: =IF(_CALC!$C$117=0,"",IFERROR(INDEX(ADHOC!$A$2:$BZ$20001,_CALC!$C$117,MATCH("Planner Bestfit Algorithm",ADHOC!$1:$1,0)),"")) | F17: =IF(_CALC!$C$117=0,"",IFERROR(INDEX(ADHOC!$A$2:$BZ$20001,_CALC!$C$117,MATCH("System Assigned Algorithm List",ADHOC!$1:$1,0)),"")) | G17: =IF(_CALC!$C$117=0,"",IFERROR(INDEX(ADHOC!$A$2:$BZ$20001,_CALC!$C$117,MATCH("Planner Additions",ADHOC!$1:$1,0)),"")) | H17: =IF(_CALC!$C$117=0,"",IFERROR(INDEX(ADHOC!$A$2:$BZ$20001,_CALC!$C$117,MATCH("System BestFit Final",ADHOC!$1:$1,0)),"")) | I17: =IF(_CALC!$B$117="","",_CALC!$H$117)
B18: =IF(_CALC!$B$118="","",_CALC!$B$118) | C18: =IF(_CALC!$C$118=0,"",IFERROR(INDEX(ADHOC!$A$2:$BZ$20001,_CALC!$C$118,MATCH("Final Segment",ADHOC!$1:$1,0)),"")) | D18: =IF(_CALC!$C$118=0,"",IFERROR(INDEX(ADHOC!$A$2:$BZ$20001,_CALC!$C$118,MATCH("System Bestfit Algorithm",ADHOC!$1:$1,0)),"")) | E18: =IF(_CALC!$C$118=0,"",IFERROR(INDEX(ADHOC!$A$2:$BZ$20001,_CALC!$C$118,MATCH("Planner Bestfit Algorithm",ADHOC!$1:$1,0)),"")) | F18: =IF(_CALC!$C$118=0,"",IFERROR(INDEX(ADHOC!$A$2:$BZ$20001,_CALC!$C$118,MATCH("System Assigned Algorithm List",ADHOC!$1:$1,0)),"")) | G18: =IF(_CALC!$C$118=0,"",IFERROR(INDEX(ADHOC!$A$2:$BZ$20001,_CALC!$C$118,MATCH("Planner Additions",ADHOC!$1:$1,0)),"")) | H18: =IF(_CALC!$C$118=0,"",IFERROR(INDEX(ADHOC!$A$2:$BZ$20001,_CALC!$C$118,MATCH("System BestFit Final",ADHOC!$1:$1,0)),"")) | I18: =IF(_CALC!$B$118="","",_CALC!$H$118)
B19: =IF(_CALC!$B$119="","",_CALC!$B$119) | C19: =IF(_CALC!$C$119=0,"",IFERROR(INDEX(ADHOC!$A$2:$BZ$20001,_CALC!$C$119,MATCH("Final Segment",ADHOC!$1:$1,0)),"")) | D19: =IF(_CALC!$C$119=0,"",IFERROR(INDEX(ADHOC!$A$2:$BZ$20001,_CALC!$C$119,MATCH("System Bestfit Algorithm",ADHOC!$1:$1,0)),"")) | E19: =IF(_CALC!$C$119=0,"",IFERROR(INDEX(ADHOC!$A$2:$BZ$20001,_CALC!$C$119,MATCH("Planner Bestfit Algorithm",ADHOC!$1:$1,0)),"")) | F19: =IF(_CALC!$C$119=0,"",IFERROR(INDEX(ADHOC!$A$2:$BZ$20001,_CALC!$C$119,MATCH("System Assigned Algorithm List",ADHOC!$1:$1,0)),"")) | G19: =IF(_CALC!$C$119=0,"",IFERROR(INDEX(ADHOC!$A$2:$BZ$20001,_CALC!$C$119,MATCH("Planner Additions",ADHOC!$1:$1,0)),"")) | H19: =IF(_CALC!$C$119=0,"",IFERROR(INDEX(ADHOC!$A$2:$BZ$20001,_CALC!$C$119,MATCH("System BestFit Final",ADHOC!$1:$1,0)),"")) | I19: =IF(_CALC!$B$119="","",_CALC!$H$119)
B20: =IF(_CALC!$B$120="","",_CALC!$B$120) | C20: =IF(_CALC!$C$120=0,"",IFERROR(INDEX(ADHOC!$A$2:$BZ$20001,_CALC!$C$120,MATCH("Final Segment",ADHOC!$1:$1,0)),"")) | D20: =IF(_CALC!$C$120=0,"",IFERROR(INDEX(ADHOC!$A$2:$BZ$20001,_CALC!$C$120,MATCH("System Bestfit Algorithm",ADHOC!$1:$1,0)),"")) | E20: =IF(_CALC!$C$120=0,"",IFERROR(INDEX(ADHOC!$A$2:$BZ$20001,_CALC!$C$120,MATCH("Planner Bestfit Algorithm",ADHOC!$1:$1,0)),"")) | F20: =IF(_CALC!$C$120=0,"",IFERROR(INDEX(ADHOC!$A$2:$BZ$20001,_CALC!$C$120,MATCH("System Assigned Algorithm List",ADHOC!$1:$1,0)),"")) | G20: =IF(_CALC!$C$120=0,"",IFERROR(INDEX(ADHOC!$A$2:$BZ$20001,_CALC!$C$120,MATCH("Planner Additions",ADHOC!$1:$1,0)),"")) | H20: =IF(_CALC!$C$120=0,"",IFERROR(INDEX(ADHOC!$A$2:$BZ$20001,_CALC!$C$120,MATCH("System BestFit Final",ADHOC!$1:$1,0)),"")) | I20: =IF(_CALC!$B$120="","",_CALC!$H$120)
B22: SIMULACIÓN · elige un BestFit (y algoritmo si es ST) por intersección
B23: CFG | C23: BestFit simulado | D23: Algoritmo simulado (sólo si ST) | E23: Curva que sustituye a System FC | F23: Estado | G23: Δ total meses futuros
B24: =IF(_CALC!$B$113="","",_CALC!$B$113) | C24: (SISTEMA) | D24: (ST BestFit) | E24: =IF(_CALC!$B$113="","",IF(_CALC!$K$113="","(sin cambio)",_CALC!$K$113)) | F24: =IF(_CALC!$B$113="","",_CALC!$M$113) | G24: =IF(_CALC!$B$113="","",SUM(_CALC!$D$123:$AM$123)-SUM(_CALC!$D$133:$AM$133))
B25: =IF(_CALC!$B$114="","",_CALC!$B$114) | C25: (SISTEMA) | D25: (ST BestFit) | E25: =IF(_CALC!$B$114="","",IF(_CALC!$K$114="","(sin cambio)",_CALC!$K$114)) | F25: =IF(_CALC!$B$114="","",_CALC!$M$114) | G25: =IF(_CALC!$B$114="","",SUM(_CALC!$D$124:$AM$124)-SUM(_CALC!$D$134:$AM$134))
B26: =IF(_CALC!$B$115="","",_CALC!$B$115) | C26: (SISTEMA) | D26: (ST BestFit) | E26: =IF(_CALC!$B$115="","",IF(_CALC!$K$115="","(sin cambio)",_CALC!$K$115)) | F26: =IF(_CALC!$B$115="","",_CALC!$M$115) | G26: =IF(_CALC!$B$115="","",SUM(_CALC!$D$125:$AM$125)-SUM(_CALC!$D$135:$AM$135))
B27: =IF(_CALC!$B$116="","",_CALC!$B$116) | C27: (SISTEMA) | D27: (ST BestFit) | E27: =IF(_CALC!$B$116="","",IF(_CALC!$K$116="","(sin cambio)",_CALC!$K$116)) | F27: =IF(_CALC!$B$116="","",_CALC!$M$116) | G27: =IF(_CALC!$B$116="","",SUM(_CALC!$D$126:$AM$126)-SUM(_CALC!$D$136:$AM$136))
B28: =IF(_CALC!$B$117="","",_CALC!$B$117) | C28: (SISTEMA) | D28: (ST BestFit) | E28: =IF(_CALC!$B$117="","",IF(_CALC!$K$117="","(sin cambio)",_CALC!$K$117)) | F28: =IF(_CALC!$B$117="","",_CALC!$M$117) | G28: =IF(_CALC!$B$117="","",SUM(_CALC!$D$127:$AM$127)-SUM(_CALC!$D$137:$AM$137))
B29: =IF(_CALC!$B$118="","",_CALC!$B$118) | C29: (SISTEMA) | D29: (ST BestFit) | E29: =IF(_CALC!$B$118="","",IF(_CALC!$K$118="","(sin cambio)",_CALC!$K$118)) | F29: =IF(_CALC!$B$118="","",_CALC!$M$118) | G29: =IF(_CALC!$B$118="","",SUM(_CALC!$D$128:$AM$128)-SUM(_CALC!$D$138:$AM$138))
B30: =IF(_CALC!$B$119="","",_CALC!$B$119) | C30: (SISTEMA) | D30: (ST BestFit) | E30: =IF(_CALC!$B$119="","",IF(_CALC!$K$119="","(sin cambio)",_CALC!$K$119)) | F30: =IF(_CALC!$B$119="","",_CALC!$M$119) | G30: =IF(_CALC!$B$119="","",SUM(_CALC!$D$129:$AM$129)-SUM(_CALC!$D$139:$AM$139))
B31: =IF(_CALC!$B$120="","",_CALC!$B$120) | C31: (SISTEMA) | D31: (ST BestFit) | E31: =IF(_CALC!$B$120="","",IF(_CALC!$K$120="","(sin cambio)",_CALC!$K$120)) | F31: =IF(_CALC!$B$120="","",_CALC!$M$120) | G31: =IF(_CALC!$B$120="","",SUM(_CALC!$D$130:$AM$130)-SUM(_CALC!$D$140:$AM$140))
B33: Consensus total en meses futuros (según el filtro CFG de arriba): | E33: =IF(_CALC!$F$14=0,"—","actual "&TEXT(SUMPRODUCT(_CALC!$D$30:$AM$30,_CALC!$D$161:$AM$161),"#,##0")&" → simulado "&TEXT(SUMPRODUCT(_CALC!$D$30:$AM$30,_CALC!$D$162:$AM$162),"#,##0")&" (Δ "&TEXT(SUMPRODUCT(_CALC!$D$30:$AM$30,_CALC!$D$162:$AM$162)-SUMPRODUCT(_CALC!$D$30:$AM$30,_CALC!$D$161:$AM$161),"+#,##0;-#,##0;0")&")")
B92: CÓMO FUNCIONA
B93: • Celdas amarillas = entradas. Todo lo demás son fórmulas; no hay macros.
B94: • Gráfico 1: línea continua gruesa = Consensus - Final de la versión actual. Las demás curvas de CONSENSUS van continuas, las de BESTFIT a trazos y las de ALGO punteadas.
B95: • De ALGO sólo se dibujan las curvas con valores para el EAN (hasta 12). Se excluyen Stat Fcst L1, System ML Fcst L1 y System Stat Fcst Bestfit por ser duplicados de ST Stat Fcst (ver _CALC!A200:A202).
B96: • En modo (TODOS) las curvas se suman sobre todos los CFG del EAN. Si un algoritmo sólo existe en parte de las intersecciones, la leyenda lo marca como "parcial n/N".
B97: • Gráfico 2: la elección de la tabla de simulación sustituye a System FC - Final sólo en los meses futuros; el consensus simulado = consensus actual + (system simulado − system original), con piso en 0. Las demás capas del consensus se mantienen sin tocar.
B98: • Un algoritmo sin valor en un mes cuenta como 0. Las intersecciones sin filas en BESTFIT/ALGO (p.ej. P_US_FG) no son simulables y se dejan con su forecast original.
B99: • Para repegar datos: pega sobre CONSENSUS, BESTFIT, ALGO y ADHOC respetando la fila 1 de cabeceras. Las columnas y los meses se localizan por nombre de cabecera, hasta 36 meses y 20.000 filas por pestaña.
B100: • El eje X sale de la fila 1 de CONSENSUS. Los meses anteriores al "primer mes futuro" se marcan (hist).
B101: • Los gráficos están dibujados sobre 12 meses (_CALC!D:O, filas 34-50 y 163-168) y sobre 10 huecos para curvas de ALGO (el máximo visto por EAN es 6; los huecos sin usar salen como "—" en la leyenda). Si algún día pegas otro horizonte o aparece un EAN con más algoritmos, sale un aviso en rojo arriba: sólo hay que ampliar el rango de las series. _CALC ya calcula hasta 36 meses y 30 capas.

Sheet CONSENSUS
A1: House | B1: Brand | C1: Product Line | D1: EAN | E1: Planning Item Description | F1: CFG | G1: Version Name | H1: Data | I1: 2026.M07 | J1: 2026.M08 | K1: 2026.M09 | L1: 2026.M10 | M1: 2026.M11 | N1: 2026.M12 | O1: 2027.M01 | P1: 2027.M02 | Q1: 2027.M03 | R1: 2027.M04 | S1: 2027.M05 | T1: 2027.M06
A2: Gucci | B2: Gucci Guilty (00840) | C2: Gucci Guilty PH Eau de Parfum (00005405) | D2: 3614229382112 | E2: GG PH P EDP 50 ML IV | F2: P_US_ALL_OTHERS | G2: CurrentWorkingView | H2: Consensus - Final LY M | I2: 556 | J2: 602 | K2: 3372 | L2: 1477 | M2: 74 | N2: 1551 | O2: 155 | P2: 1256 | Q2: 2277 | R2: 2635 | S2: 1388 | T2: 2607
A3: Gucci | B3: Gucci Guilty (00840) | C3: Gucci Guilty PH Eau de Parfum (00005405) | D3: 3614229382112 | E3: GG PH P EDP 50 ML IV | F3: P_US_ALL_OTHERS | G3: CurrentWorkingView | H3: System FC - Final | I3: 2386 | J3: 617 | K3: 805 | L3: 2610 | M3: 922 | N3: 673 | O3: 695 | P3: 1392 | Q3: 1280 | R3: 758 | S3: 1315 | T3: 716
A4: Gucci | B4: Gucci Guilty (00840) | C4: Gucci Guilty PH Eau de Parfum (00005405) | D4: 3614229382112 | E4: GG PH P EDP 50 ML IV | F4: P_US_ALL_OTHERS | G4: CurrentWorkingView | H4: EPOS | I4: 1333
A5: Gucci | B5: Gucci Guilty (00840) | C5: Gucci Guilty PH Eau de Parfum (00005405) | D5: 3614229382112 | E5: GG PH P EDP 50 ML IV | F5: P_US_ALL_OTHERS | G5: CurrentWorkingView | H5: Reasonability Adjustment | J5: -1292 | K5: 365 | L5: 780 | O5: -1283 | P5: -235 | Q5: -733 | S5: -1000 | T5: -843
A6: Gucci | B6: Gucci Guilty (00840) | C6: Gucci Guilty PH Eau de Parfum (00005405) | D6: 3614229382112 | E6: GG PH P EDP 50 ML IV | F6: P_US_ALL_OTHERS | G6: CurrentWorkingView | H6: Total Demand Assumption
A7: Gucci | B7: Gucci Guilty (00840) | C7: Gucci Guilty PH Eau de Parfum (00005405) | D7: 3614229382112 | E7: GG PH P EDP 50 ML IV | F7: P_US_ALL_OTHERS | G7: CurrentWorkingView | H7: Consensus - Final | I7: 2386 | J7: 617 | K7: 1008.7822 | L7: 3390 | M7: 922 | N7: 673 | P7: 1157 | Q7: 547 | R7: 758 | S7: 315 | T7: 72
A8: Gucci | B8: Gucci Guilty (00840) | C8: Gucci Guilty PH Eau de Parfum (00005405) | D8: 3614229382112 | E8: GG PH P EDP 50 ML IV | F8: P_US_ALL_OTHERS | G8: CurrentWorkingView | H8: Supply Cuts | I8: 37
A9: Gucci | B9: Gucci Guilty (00840) | C9: Gucci Guilty PH Eau de Parfum (00005405) | D9: 3614229382112 | E9: GG PH P EDP 50 ML IV | F9: P_US_ALL_OTHERS | G9: Month-2026.M09.W38 | H9: Consensus - Final LY M | I9: 556 | J9: 602 | K9: 3372 | L9: 1477 | M9: 74 | N9: 1551 | O9: 155 | P9: 1256 | Q9: 2277 | R9: 2635 | S9: 1388 | T9: 2607
A10: Gucci | B10: Gucci Guilty (00840) | C10: Gucci Guilty PH Eau de Parfum (00005405) | D10: 3614229382112 | E10: GG PH P EDP 50 ML IV | F10: P_US_ALL_OTHERS | G10: Month-2026.M09.W38 | H10: System FC - Final | I10: 2386 | J10: 617 | K10: 738 | L10: 620 | M10: 618 | N10: 1328 | O10: 2484 | P10: 776 | Q10: 1395 | R10: 695 | S10: 1404 | T10: 1720
A11: Gucci | B11: Gucci Guilty (00840) | C11: Gucci Guilty PH Eau de Parfum (00005405) | D11: 3614229382112 | E11: GG PH P EDP 50 ML IV | F11: P_US_ALL_OTHERS | G11: Month-2026.M09.W38 | H11: EPOS | I11: 1333
A12: Gucci | B12: Gucci Guilty (00840) | C12: Gucci Guilty PH Eau de Parfum (00005405) | D12: 3614229382112 | E12: GG PH P EDP 50 ML IV | F12: P_US_ALL_OTHERS | G12: Month-2026.M09.W38 | H12: Reasonability Adjustment | J12: -1292 | K12: 365 | L12: 780 | O12: -1283 | P12: -235 | Q12: -733 | S12: -1000 | T12: -843
A13: Gucci | B13: Gucci Guilty (00840) | C13: Gucci Guilty PH Eau de Parfum (00005405) | D13: 3614229382112 | E13: GG PH P EDP 50 ML IV | F13: P_US_ALL_OTHERS | G13: Month-2026.M09.W38 | H13: Total Demand Assumption
A14: Gucci | B14: Gucci Guilty (00840) | C14: Gucci Guilty PH Eau de Parfum (00005405) | D14: 3614229382112 | E14: GG PH P EDP 50 ML IV | F14: P_US_ALL_OTHERS | G14: Month-2026.M09.W38 | H14: Consensus - Final | I14: 2386 | J14: 617 | K14: 1008.7822 | L14: 1400 | M14: 618 | N14: 1328 | O14: 1201 | P14: 541 | Q14: 662 | R14: 695 | S14: 404 | T14: 877
A15: Gucci | B15: Gucci Guilty (00840) | C15: Gucci Guilty PH Eau de Parfum (00005405) | D15: 3614229382112 | E15: GG PH P EDP 50 ML IV | F15: P_US_ALL_OTHERS | G15: Month-2026.M09.W38 | H15: Supply Cuts | I15: 37
A16: Gucci | B16: Gucci Guilty (00840) | C16: Gucci Guilty PH Eau de Parfum (00005405) | D16: 3614229382112 | E16: GG PH P EDP 50 ML IV | F16: P_US_FG | G16: CurrentWorkingView | H16: Consensus - Final LY M | J16: 3 | K16: 1
A17: Gucci | B17: Gucci Guilty (00840) | C17: Gucci Guilty PH Eau de Parfum (00005405) | D17: 3614229382112 | E17: GG PH P EDP 50 ML IV | F17: P_US_FG | G17: CurrentWorkingView | H17: System FC - Final | K17: 0 | L17: 0 | M17: 0 | N17: 0 | O17: 0 | P17: 0 | Q17: 0 | R17: 0 | S17: 0 | T17: 0
A18: Gucci | B18: Gucci Guilty (00840) | C18: Gucci Guilty PH Eau de Parfum (00005405) | D18: 3614229382112 | E18: GG PH P EDP 50 ML IV | F18: P_US_FG | G18: CurrentWorkingView | H18: EPOS
A19: Gucci | B19: Gucci Guilty (00840) | C19: Gucci Guilty PH Eau de Parfum (00005405) | D19: 3614229382112 | E19: GG PH P EDP 50 ML IV | F19: P_US_FG | G19: CurrentWorkingView | H19: Reasonability Adjustment | K19: 0 | L19: 0 | N19: 0 | O19: 0 | P19: 0 | Q19: 0 | R19: 0
A20: Gucci | B20: Gucci Guilty (00840) | C20: Gucci Guilty PH Eau de Parfum (00005405) | D20: 3614229382112 | E20: GG PH P EDP 50 ML IV | F20: P_US_FG | G20: CurrentWorkingView | H20: Total Demand Assumption
A21: Gucci | B21: Gucci Guilty (00840) | C21: Gucci Guilty PH Eau de Parfum (00005405) | D21: 3614229382112 | E21: GG PH P EDP 50 ML IV | F21: P_US_FG | G21: CurrentWorkingView | H21: Consensus - Final | K21: 0 | L21: 0 | N21: 0 | O21: 0 | P21: 0 | Q21: 0 | R21: 0
A22: Gucci | B22: Gucci Guilty (00840) | C22: Gucci Guilty PH Eau de Parfum (00005405) | D22: 3614229382112 | E22: GG PH P EDP 50 ML IV | F22: P_US_FG | G22: CurrentWorkingView | H22: Supply Cuts
A23: Gucci | B23: Gucci Guilty (00840) | C23: Gucci Guilty PH Eau de Parfum (00005405) | D23: 3614229382112 | E23: GG PH P EDP 50 ML IV | F23: P_US_FG | G23: Month-2026.M09.W38 | H23: Consensus - Final LY M | J23: 3 | K23: 1
A24: Gucci | B24: Gucci Guilty (00840) | C24: Gucci Guilty PH Eau de Parfum (00005405) | D24: 3614229382112 | E24: GG PH P EDP 50 ML IV | F24: P_US_FG | G24: Month-2026.M09.W38 | H24: System FC - Final | K24: 0 | L24: 0 | M24: 0 | N24: 0 | O24: 0 | P24: 0 | Q24: 0 | R24: 0 | S24: 0
A25: Gucci | B25: Gucci Guilty (00840) | C25: Gucci Guilty PH Eau de Parfum (00005405) | D25: 3614229382112 | E25: GG PH P EDP 50 ML IV | F25: P_US_FG | G25: Month-2026.M09.W38 | H25: EPOS
A26: Gucci | B26: Gucci Guilty (00840) | C26: Gucci Guilty PH Eau de Parfum (00005405) | D26: 3614229382112 | E26: GG PH P EDP 50 ML IV | F26: P_US_FG | G26: Month-2026.M09.W38 | H26: Reasonability Adjustment | K26: 0 | L26: 0 | N26: 0 | O26: 0 | P26: 0 | Q26: 0 | R26: 0
A27: Gucci | B27: Gucci Guilty (00840) | C27: Gucci Guilty PH Eau de Parfum (00005405) | D27: 3614229382112 | E27: GG PH P EDP 50 ML IV | F27: P_US_FG | G27: Month-2026.M09.W38 | H27: Total Demand Assumption
A28: Gucci | B28: Gucci Guilty (00840) | C28: Gucci Guilty PH Eau de Parfum (00005405) | D28: 3614229382112 | E28: GG PH P EDP 50 ML IV | F28: P_US_FG | G28: Month-2026.M09.W38 | H28: Consensus - Final | K28: 0 | L28: 0 | N28: 0 | O28: 0 | P28: 0 | Q28: 0 | R28: 0
A29: Gucci | B29: Gucci Guilty (00840) | C29: Gucci Guilty PH Eau de Parfum (00005405) | D29: 3614229382112 | E29: GG PH P EDP 50 ML IV | F29: P_US_FG | G29: Month-2026.M09.W38 | H29: Supply Cuts
A30: Gucci | B30: Gucci Guilty (00840) | C30: Gucci Guilty PH Eau de Parfum (00005405) | D30: 3614229382112 | E30: GG PH P EDP 50 ML IV | F30: P_US_ULTA | G30: CurrentWorkingView | H30: Consensus - Final LY M | I30: 172 | J30: 751 | K30: 618 | L30: 79 | M30: 635 | N30: 652 | P30: 475 | Q30: 230 | R30: 186 | S30: 691 | T30: 249
A31: Gucci | B31: Gucci Guilty (00840) | C31: Gucci Guilty PH Eau de Parfum (00005405) | D31: 3614229382112 | E31: GG PH P EDP 50 ML IV | F31: P_US_ULTA | G31: CurrentWorkingView | H31: System FC - Final | I31: 166 | J31: 331 | K31: 521 | L31: 0 | M31: 248 | N31: 177 | O31: 40 | P31: 852 | Q31: 487 | R31: 55 | S31: 376 | T31: 540
A32: Gucci | B32: Gucci Guilty (00840) | C32: Gucci Guilty PH Eau de Parfum (00005405) | D32: 3614229382112 | E32: GG PH P EDP 50 ML IV | F32: P_US_ULTA | G32: CurrentWorkingView | H32: EPOS | I32: 248
A33: Gucci | B33: Gucci Guilty (00840) | C33: Gucci Guilty PH Eau de Parfum (00005405) | D33: 3614229382112 | E33: GG PH P EDP 50 ML IV | F33: P_US_ULTA | G33: CurrentWorkingView | H33: Reasonability Adjustment | J33: -208 | K33: 235 | L33: 20 | O33: -217 | P33: -165 | Q33: -267 | T33: -157
A34: Gucci | B34: Gucci Guilty (00840) | C34: Gucci Guilty PH Eau de Parfum (00005405) | D34: 3614229382112 | E34: GG PH P EDP 50 ML IV | F34: P_US_ULTA | G34: CurrentWorkingView | H34: Total Demand Assumption
A35: Gucci | B35: Gucci Guilty (00840) | C35: Gucci Guilty PH Eau de Parfum (00005405) | D35: 3614229382112 | E35: GG PH P EDP 50 ML IV | F35: P_US_ULTA | G35: CurrentWorkingView | H35: Consensus - Final | I35: 166 | J35: 331 | K35: 630.21781 | L35: 20 | M35: 248 | N35: 177 | P35: 687 | Q35: 220 | R35: 55 | S35: 376 | T35: 383
A36: Gucci | B36: Gucci Guilty (00840) | C36: Gucci Guilty PH Eau de Parfum (00005405) | D36: 3614229382112 | E36: GG PH P EDP 50 ML IV | F36: P_US_ULTA | G36: CurrentWorkingView | H36: Supply Cuts
A37: Gucci | B37: Gucci Guilty (00840) | C37: Gucci Guilty PH Eau de Parfum (00005405) | D37: 3614229382112 | E37: GG PH P EDP 50 ML IV | F37: P_US_ULTA | G37: Month-2026.M09.W38 | H37: Consensus - Final LY M | I37: 172 | J37: 751 | K37: 618 | L37: 79 | M37: 635 | N37: 652 | P37: 475 | Q37: 230 | R37: 186 | S37: 691 | T37: 249
A38: Gucci | B38: Gucci Guilty (00840) | C38: Gucci Guilty PH Eau de Parfum (00005405) | D38: 3614229382112 | E38: GG PH P EDP 50 ML IV | F38: P_US_ULTA | G38: Month-2026.M09.W38 | H38: System FC - Final | I38: 166 | J38: 331 | K38: 433 | L38: 16 | M38: 446 | N38: 522 | O38: 421 | P38: 544 | Q38: 509 | R38: 412 | S38: 323 | T38: 320
A39: Gucci | B39: Gucci Guilty (00840) | C39: Gucci Guilty PH Eau de Parfum (00005405) | D39: 3614229382112 | E39: GG PH P EDP 50 ML IV | F39: P_US_ULTA | G39: Month-2026.M09.W38 | H39: EPOS | I39: 248
A40: Gucci | B40: Gucci Guilty (00840) | C40: Gucci Guilty PH Eau de Parfum (00005405) | D40: 3614229382112 | E40: GG PH P EDP 50 ML IV | F40: P_US_ULTA | G40: Month-2026.M09.W38 | H40: Reasonability Adjustment | J40: -208 | K40: 235 | L40: 20 | O40: -217 | P40: -165 | Q40: -267 | T40: -157
...

Sheet BESTFIT
A1: Version Name | B1: ST Stat Item | C1: ST Stat Account | D1: Data | E1: 2026.M07 | F1: 2026.M08 | G1: 2026.M09 | H1: 2026.M10 | I1: 2026.M11 | J1: 2026.M12 | K1: 2027.M01 | L1: 2027.M02 | M1: 2027.M03 | N1: 2027.M04 | O1: 2027.M05 | P1: 2027.M06
A2: CurrentWorkingView | B2: 3614229382112 | C2: P_US_ALL_OTHERS | D2: System FC - Final | E2: 2386 | F2: 617 | G2: 805 | H2: 2610 | I2: 922 | J2: 673 | K2: 695 | L2: 1392 | M2: 1280 | N2: 758 | O2: 1315 | P2: 716
A3: CurrentWorkingView | B3: 3614229382112 | C3: P_US_ALL_OTHERS | D3: CML Fcst | H3: 1696 | I3: 536 | J3: 1435 | K3: 846 | L3: 1296 | M3: 1408 | N3: 1633 | O3: 1116 | P3: 2130
A4: CurrentWorkingView | B4: 3614229382112 | C4: P_US_ALL_OTHERS | D4: ST Stat Fcst | E4: 2386 | F4: 617 | G4: 660 | H4: 2609 | I4: 922 | J4: 673 | K4: 695 | L4: 1392 | M4: 1280 | N4: 758 | O4: 1315 | P4: 716
A5: CurrentWorkingView | B5: 3614229382112 | C5: P_US_ALL_OTHERS | D5: LT Stat Fcst | H5: 2051 | I5: 2048 | J5: 2042 | K5: 2045 | L5: 2044 | M5: 2041 | N5: 2041 | O5: 2041 | P5: 1836
A6: CurrentWorkingView | B6: 3614229382112 | C6: P_US_ALL_OTHERS | D6: System BestFit Final | E6: ST | F6: ST | G6: ST | H6: ST | I6: ST | J6: ST | K6: ST | L6: ST | M6: ST | N6: ST | O6: ST | P6: ST
A7: CurrentWorkingView | B7: 3614229382112 | C7: P_US_ALL_OTHERS | D7: System Bestfit Model ST | E7: ST | F7: ST | G7: ST | H7: ST | I7: ST | J7: ST | K7: ST | L7: ST | M7: ST | N7: ST | O7: ST | P7: ST
A8: CurrentWorkingView | B8: 3614229382112 | C8: P_US_ALL_OTHERS | D8: Planner BestFit Model | E8: ST | F8: ST | G8: ST | H8: ST | I8: ST | J8: ST | K8: ST | L8: ST | M8: ST | N8: ST | O8: ST | P8: ST
A9: CurrentWorkingView | B9: 3614229382112 | C9: P_US_ULTA | D9: System FC - Final | E9: 166 | F9: 331 | G9: 521 | H9: 0 | I9: 248 | J9: 177 | K9: 40 | L9: 852 | M9: 487 | N9: 55 | O9: 376 | P9: 540
A10: CurrentWorkingView | B10: 3614229382112 | C10: P_US_ULTA | D10: CML Fcst | H10: 398 | I10: 754 | J10: 700 | K10: 288 | L10: 532 | M10: 328 | N10: 223 | O10: 523 | P10: 253
A11: CurrentWorkingView | B11: 3614229382112 | C11: P_US_ULTA | D11: ST Stat Fcst | E11: 166 | F11: 331 | G11: 428 | H11: 0 | I11: 248 | J11: 177 | K11: 40 | L11: 852 | M11: 487 | N11: 55 | O11: 376 | P11: 540
A12: CurrentWorkingView | B12: 3614229382112 | C12: P_US_ULTA | D12: LT Stat Fcst | H12: 288 | I12: 288 | J12: 292 | K12: 288 | L12: 288 | M12: 288 | N12: 288 | O12: 288 | P12: 259
A13: CurrentWorkingView | B13: 3614229382112 | C13: P_US_ULTA | D13: System BestFit Final | E13: ST | F13: ST | G13: ST | H13: ST | I13: ST | J13: ST | K13: ST | L13: ST | M13: ST | N13: ST | O13: ST | P13: ST
A14: CurrentWorkingView | B14: 3614229382112 | C14: P_US_ULTA | D14: System Bestfit Model ST | E14: ST | F14: ST | G14: ST | H14: ST | I14: ST | J14: ST | K14: ST | L14: ST | M14: ST | N14: ST | O14: ST | P14: ST
A15: CurrentWorkingView | B15: 3614229382112 | C15: P_US_ULTA | D15: Planner BestFit Model | E15: ST | F15: ST | G15: ST | H15: ST | I15: ST | J15: ST | K15: ST | L15: ST | M15: ST | N15: ST | O15: ST | P15: ST
A16: CurrentWorkingView | B16: 3614229382129 | C16: P_US_ALL_OTHERS | D16: System FC - Final | E16: 3672 | F16: 2128 | G16: 1932 | H16: 3455 | I16: 1723 | J16: 2914 | K16: 1063 | L16: 1044 | M16: 992 | N16: 1325 | O16: 2825 | P16: 2250
A17: CurrentWorkingView | B17: 3614229382129 | C17: P_US_ALL_OTHERS | D17: CML Fcst | H17: 4162 | I17: 2202 | J17: 2768 | K17: 1298 | L17: 1108 | M17: 2458 | N17: 1783 | O17: 1949 | P17: 1590
A18: CurrentWorkingView | B18: 3614229382129 | C18: P_US_ALL_OTHERS | D18: ST Stat Fcst | E18: 3672 | F18: 2128 | G18: 1932 | H18: 3455 | I18: 1722 | J18: 2914 | K18: 1063 | L18: 1044 | M18: 992 | N18: 1325 | O18: 2825 | P18: 2250
A19: CurrentWorkingView | B19: 3614229382129 | C19: P_US_ALL_OTHERS | D19: LT Stat Fcst | H19: 2790 | I19: 2782 | J19: 2777 | K19: 2777 | L19: 2776 | M19: 2777 | N19: 2777 | O19: 2776 | P19: 2499
A20: CurrentWorkingView | B20: 3614229382129 | C20: P_US_ALL_OTHERS | D20: System BestFit Final | E20: ST | F20: ST | G20: ST | H20: ST | I20: ST | J20: ST | K20: ST | L20: ST | M20: ST | N20: ST | O20: ST | P20: ST
A21: CurrentWorkingView | B21: 3614229382129 | C21: P_US_ALL_OTHERS | D21: System Bestfit Model ST | E21: ST | F21: ST | G21: ST | H21: ST | I21: ST | J21: ST | K21: ST | L21: ST | M21: ST | N21: ST | O21: ST | P21: ST
A22: CurrentWorkingView | B22: 3614229382129 | C22: P_US_ALL_OTHERS | D22: Planner BestFit Model | E22: ST | F22: ST | G22: ST | H22: ST | I22: ST | J22: ST | K22: ST | L22: ST | M22: ST | N22: ST | O22: ST | P22: ST
A23: CurrentWorkingView | B23: 3614229382129 | C23: P_US_ULTA | D23: System FC - Final | E23: 471 | F23: 608 | G23: 1177 | H23: 1180 | I23: 1177 | J23: 1173 | K23: 1174 | L23: 1172 | M23: 1174 | N23: 1174 | O23: 1174 | P23: 1057
A24: CurrentWorkingView | B24: 3614229382129 | C24: P_US_ULTA | D24: CML Fcst | H24: 832 | I24: 1380 | J24: 1821 | K24: 819 | L24: 580 | M24: 899 | N24: 403 | O24: 917 | P24: 334
A25: CurrentWorkingView | B25: 3614229382129 | C25: P_US_ULTA | D25: ST Stat Fcst | E25: 471 | F25: 608 | G25: 1790 | H25: 558 | I25: 1474 | J25: 1661 | K25: 731 | L25: 1344 | M25: 1789 | N25: 608 | O25: 2507 | P25: 703
A26: CurrentWorkingView | B26: 3614229382129 | C26: P_US_ULTA | D26: LT Stat Fcst | H26: 1181 | I26: 1178 | J26: 1173 | K26: 1174 | L26: 1172 | M26: 1174 | N26: 1174 | O26: 1174 | P26: 1057
A27: CurrentWorkingView | B27: 3614229382129 | C27: P_US_ULTA | D27: System BestFit Final | E27: LT | F27: LT | G27: LT | H27: LT | I27: LT | J27: LT | K27: LT | L27: LT | M27: LT | N27: LT | O27: LT | P27: LT
A28: CurrentWorkingView | B28: 3614229382129 | C28: P_US_ULTA | D28: System Bestfit Model ST
A29: CurrentWorkingView | B29: 3614229382129 | C29: P_US_ULTA | D29: Planner BestFit Model | E29: LT | F29: LT | G29: LT | H29: LT | I29: LT | J29: LT | K29: LT | L29: LT | M29: LT | N29: LT | O29: LT | P29: LT
A30: CurrentWorkingView | B30: 3616301794639 | C30: P_US_ALL_OTHERS | D30: System FC - Final | E30: 53 | F30: 90 | G30: 112 | H30: 612 | I30: 76 | J30: 76 | K30: 75 | L30: 468 | M30: 208 | N30: 77 | O30: 75 | P30: 70
A31: CurrentWorkingView | B31: 3616301794639 | C31: P_US_ALL_OTHERS | D31: CML Fcst | H31: 594 | I31: 420 | J31: 394 | K31: 151 | L31: 152 | M31: 159 | N31: 142 | O31: 128 | P31: 94
A32: CurrentWorkingView | B32: 3616301794639 | C32: P_US_ALL_OTHERS | D32: ST Stat Fcst | E32: 53 | F32: 90 | G32: 362 | H32: 1307 | I32: 960 | J32: 753 | K32: 385 | L32: 812 | M32: 332 | N32: 540 | O32: 376 | P32: 382
A33: CurrentWorkingView | B33: 3616301794639 | C33: P_US_ALL_OTHERS | D33: LT Stat Fcst | H33: 612 | I33: 76 | J33: 76 | K33: 75 | L33: 468 | M33: 208 | N33: 77 | O33: 75 | P33: 70
A34: CurrentWorkingView | B34: 3616301794639 | C34: P_US_ALL_OTHERS | D34: System BestFit Final | E34: LT | F34: LT | G34: LT | H34: LT | I34: LT | J34: LT | K34: LT | L34: LT | M34: LT | N34: LT | O34: LT | P34: LT
A35: CurrentWorkingView | B35: 3616301794639 | C35: P_US_ALL_OTHERS | D35: System Bestfit Model ST
A36: CurrentWorkingView | B36: 3616301794639 | C36: P_US_ALL_OTHERS | D36: Planner BestFit Model | E36: LT | F36: LT | G36: LT | H36: LT | I36: LT | J36: LT | K36: LT | L36: LT | M36: LT | N36: LT | O36: LT | P36: LT
A37: CurrentWorkingView | B37: 3616301794639 | C37: P_US_ULTA | D37: System FC - Final | E37: 89 | F37: 98 | G37: 100 | H37: 270 | I37: 34 | J37: 35 | K37: 35 | L37: 212 | M37: 93 | N37: 34 | O37: 36 | P37: 31
A38: CurrentWorkingView | B38: 3616301794639 | C38: P_US_ULTA | D38: CML Fcst | H38: 457 | I38: 138 | J38: 151 | K38: 120 | L38: 120 | M38: 208 | N38: 77 | O38: 248 | P38: 72
A39: CurrentWorkingView | B39: 3616301794639 | C39: P_US_ULTA | D39: ST Stat Fcst | E39: 89 | F39: 98 | G39: 145 | H39: 239 | I39: 176 | J39: 164 | K39: 177 | L39: 196 | M39: 190 | N39: 180 | O39: 182 | P39: 185
A40: CurrentWorkingView | B40: 3616301794639 | C40: P_US_ULTA | D40: LT Stat Fcst | H40: 271 | I40: 34 | J40: 35 | K40: 35 | L40: 212 | M40: 93 | N40: 34 | O40: 36 | P40: 31
...

Sheet ALGO
A1: ST Stat Item | B1: Stat Item Description | C1: ST Stat Account | D1: Data | E1: 2026.M07 | F1: 2026.M08 | G1: 2026.M09 | H1: 2026.M10 | I1: 2026.M11 | J1: 2026.M12 | K1: 2027.M01 | L1: 2027.M02 | M1: 2027.M03 | N1: 2027.M04 | O1: 2027.M05 | P1: 2027.M06
A2: 3614229382112 | B2: GG PH P EDP 50 ML IV | C2: P_US_ALL_OTHERS | D2: Stat Fcst L1 | E2: 2385.9999 | F2: 616.99998 | G2: 887 | H2: 2609 | I2: 922 | J2: 673 | K2: 695 | L2: 1392 | M2: 1280 | N2: 758 | O2: 1315 | P2: 716
A3: 3614229382112 | B3: GG PH P EDP 50 ML IV | C3: P_US_ALL_OTHERS | D3: Stat Fcst AR-NNET
A4: 3614229382112 | B4: GG PH P EDP 50 ML IV | C4: P_US_ALL_OTHERS | D4: Stat Fcst Auto ARIMA
A5: 3614229382112 | B5: GG PH P EDP 50 ML IV | C5: P_US_ALL_OTHERS | D5: Stat Fcst Croston
A6: 3614229382112 | B6: GG PH P EDP 50 ML IV | C6: P_US_ALL_OTHERS | D6: Stat Fcst DES
A7: 3614229382112 | B7: GG PH P EDP 50 ML IV | C7: P_US_ALL_OTHERS | D7: Stat Fcst ETS
A8: 3614229382112 | B8: GG PH P EDP 50 ML IV | C8: P_US_ALL_OTHERS | D8: Stat Fcst Moving Average
A9: 3614229382112 | B9: GG PH P EDP 50 ML IV | C9: P_US_ALL_OTHERS | D9: Stat Fcst Naive Random Walk
A10: 3614229382112 | B10: GG PH P EDP 50 ML IV | C10: P_US_ALL_OTHERS | D10: Stat Fcst Prophet
A11: 3614229382112 | B11: GG PH P EDP 50 ML IV | C11: P_US_ALL_OTHERS | D11: Stat Fcst sARIMA
A12: 3614229382112 | B12: GG PH P EDP 50 ML IV | C12: P_US_ALL_OTHERS | D12: Stat Fcst Seasonal Naive YoY
A13: 3614229382112 | B13: GG PH P EDP 50 ML IV | C13: P_US_ALL_OTHERS | D13: Stat Fcst SES
A14: 3614229382112 | B14: GG PH P EDP 50 ML IV | C14: P_US_ALL_OTHERS | D14: Stat Fcst STLF | E14: 1662.4984 | F14: 1797.4626 | G14: 5151.8552 | H14: 3766.9401 | I14: 2201.9135 | J14: 3871.8793 | K14: 2288.1128 | L14: 3197.1029 | M14: 4902.1686 | N14: 4972.2565 | O14: 3840.1265 | P14: 4974.4234
A15: 3614229382112 | B15: GG PH P EDP 50 ML IV | C15: P_US_ALL_OTHERS | D15: Stat Fcst TBATS
A16: 3614229382112 | B16: GG PH P EDP 50 ML IV | C16: P_US_ALL_OTHERS | D16: Stat Fcst TES | E16: 962.9589 | F16: 1054.912 | G16: 2612.8199 | H16: 2608.7278 | I16: 921.50193 | J16: 672.39578 | K16: 694.91146 | L16: 1390.956 | M16: 1281.02 | N16: 756.54044 | O16: 1315.6625 | P16: 715.01216
A17: 3614229382112 | B17: GG PH P EDP 50 ML IV | C17: P_US_ALL_OTHERS | D17: Stat Fcst Theta
A18: 3614229382112 | B18: GG PH P EDP 50 ML IV | C18: P_US_ALL_OTHERS | D18: System ML Fcst L1
A19: 3614229382112 | B19: GG PH P EDP 50 ML IV | C19: P_US_ALL_OTHERS | D19: Stat Fcst Simple Snaive | E19: 2452.9999 | F19: 2259.1199 | G19: 1587.3333 | H19: 906.33331 | I19: 1323 | J19: 1075.3333 | K19: 1656 | L19: 1877.7467 | M19: 1516.6665 | N19: 1186.6667 | O19: 751.33329 | P19: 1284.6667
A20: 3614229382112 | B20: GG PH P EDP 50 ML IV | C20: P_US_ALL_OTHERS | D20: Stat Fcst Simple AOA
A21: 3614229382112 | B21: GG PH P EDP 50 ML IV | C21: P_US_ALL_OTHERS | D21: Stat Fcst Weighted Snaive
A22: 3614229382112 | B22: GG PH P EDP 50 ML IV | C22: P_US_ALL_OTHERS | D22: Stat Fcst Weighted AOA
A23: 3614229382112 | B23: GG PH P EDP 50 ML IV | C23: P_US_ALL_OTHERS | D23: Stat Fcst Growth Snaive
A24: 3614229382112 | B24: GG PH P EDP 50 ML IV | C24: P_US_ALL_OTHERS | D24: Stat Fcst Growth AOA
A25: 3614229382112 | B25: GG PH P EDP 50 ML IV | C25: P_US_ALL_OTHERS | D25: System Stat Fcst Bestfit | H25: 2608.7277 | I25: 921.50196 | J25: 672.39573 | K25: 694.91148 | L25: 1390.9561 | M25: 1281.02 | N25: 756.54048 | O25: 1315.6624 | P25: 715.01215
A26: 3614229382112 | B26: GG PH P EDP 50 ML IV | C26: P_US_ULTA | D26: Stat Fcst L1 | E26: 166 | F26: 330.99999 | G26: 570 | H26: 0 | I26: 248 | J26: 177 | K26: 40 | L26: 852 | M26: 487 | N26: 55 | O26: 376 | P26: 540
A27: 3614229382112 | B27: GG PH P EDP 50 ML IV | C27: P_US_ULTA | D27: Stat Fcst AR-NNET
A28: 3614229382112 | B28: GG PH P EDP 50 ML IV | C28: P_US_ULTA | D28: Stat Fcst Auto ARIMA
A29: 3614229382112 | B29: GG PH P EDP 50 ML IV | C29: P_US_ULTA | D29: Stat Fcst Croston
A30: 3614229382112 | B30: GG PH P EDP 50 ML IV | C30: P_US_ULTA | D30: Stat Fcst DES
A31: 3614229382112 | B31: GG PH P EDP 50 ML IV | C31: P_US_ULTA | D31: Stat Fcst ETS
A32: 3614229382112 | B32: GG PH P EDP 50 ML IV | C32: P_US_ULTA | D32: Stat Fcst Moving Average
A33: 3614229382112 | B33: GG PH P EDP 50 ML IV | C33: P_US_ULTA | D33: Stat Fcst Naive Random Walk
A34: 3614229382112 | B34: GG PH P EDP 50 ML IV | C34: P_US_ULTA | D34: Stat Fcst Prophet
A35: 3614229382112 | B35: GG PH P EDP 50 ML IV | C35: P_US_ULTA | D35: Stat Fcst sARIMA
A36: 3614229382112 | B36: GG PH P EDP 50 ML IV | C36: P_US_ULTA | D36: Stat Fcst Seasonal Naive YoY
A37: 3614229382112 | B37: GG PH P EDP 50 ML IV | C37: P_US_ULTA | D37: Stat Fcst SES
A38: 3614229382112 | B38: GG PH P EDP 50 ML IV | C38: P_US_ULTA | D38: Stat Fcst STLF | E38: 144.25486 | F38: 723.20495 | G38: 439.56449 | H38: 9.448586 | I38: 788.56403 | J38: 562.52167 | K38: 0 | L38: 118.39948 | M38: 0 | N38: 245.14972 | O38: 667.54876 | P38: 335.7483
A39: 3614229382112 | B39: GG PH P EDP 50 ML IV | C39: P_US_ULTA | D39: Stat Fcst TBATS
A40: 3614229382112 | B40: GG PH P EDP 50 ML IV | C40: P_US_ULTA | D40: Stat Fcst TES | E40: 141.79352 | F40: 652.42437 | G40: 507.8312 | H40: 0 | I40: 248.72269 | J40: 177.24742 | K40: 41.674821 | L40: 852.26788 | M40: 486.66146 | N40: 54.403426 | O40: 374.82779 | P40: 541.41678
...

Sheet ADHOC
A1: ST Stat Item | B1: Stat Item Description | C1: ST Stat Account | D1: Final Segment | E1: System Bestfit Algorithm | F1: Planner Bestfit Algorithm | G1: System Assigned Algorithm List | H1: Planner Additions | I1: System FC - Final | J1: ST Bestfit Fcst | K1: System BestFit Final
A2: 3614229382112 | B2: GG PH P EDP 50 ML IV | C2: P_US_ALL_OTHERS | D2: Horses | E2: Simple Snaive | F2: TES | G2: TES,STLF,Simple Snaive | I2: 14169 | J2: 14169 | K2: ST
A3: 3614229382112 | B3: GG PH P EDP 50 ML IV | C3: P_US_ULTA | D3: Horses | E3: STLF | F3: TES | G3: TES,STLF,Simple Snaive | I3: 3793 | J3: 3793 | K3: ST
A4: 3614229382129 | B4: GG PH P EDP 90 ML IV | C4: P_US_ALL_OTHERS | D4: Horses | E4: TES | G4: TES,STLF,Simple Snaive | I4: 25323 | J4: 25323 | K4: ST
A5: 3614229382129 | B5: GG PH P EDP 90 ML IV | C5: P_US_ULTA | D5: Horses | E5: Simple Snaive | G5: TES,STLF,Simple Snaive | I5: 12711 | J5: 12711 | K5: LT
A6: 3616301794639 | B6: GG PF EDP 90 ML INTENSE IV | C6: P_US_ALL_OTHERS | D6: Rabbits | E6: Simple Snaive | G6: TES,STLF,Simple Snaive | I6: 1992 | J6: 1992 | K6: LT
A7: 3616301794639 | B7: GG PF EDP 90 ML INTENSE IV | C7: P_US_ULTA | D7: Rabbits | E7: Moving Average | G7: DES,STLF,Weighted AOA,Moving Average | I7: 1067 | J7: 1067 | K7: LT
A8: 3616301976141 | B8: GG PF21 EDT NS 90 ML IV | C8: P_US_ALL_OTHERS | D8: Horses | E8: TES | F8: STLF | G8: TES,STLF,Simple Snaive | I8: 12496 | J8: 12496 | K8: ST
A9: 3616301976141 | B9: GG PF21 EDT NS 90 ML IV | C9: P_US_ULTA | D9: Horses | E9: Simple Snaive | F9: Simple Snaive | G9: TES,STLF,Simple Snaive | I9: 6706 | J9: 6706 | K9: ST
A10: 3616302033683 | B10: GUCCI GUILT H DEOSTK 75 ML VP IV | C10: P_US_ALL_OTHERS | D10: Rabbits | E10: Moving Average | G10: DES,STLF,Weighted AOA,Moving Average | I10: 3726 | J10: 3726 | K10: LT
A11: 3616302033683 | B11: GUCCI GUILT H DEOSTK 75 ML VP IV | C11: P_US_ULTA | D11: Rabbits | K11: ST
A12: 3616302039357 | B12: GUCCI FL GG EDP 10 ML PENSPRAY IV | C12: P_US_ALL_OTHERS | D12: Horses | E12: DES | F12: STLF | G12: DES,STLF,Weighted AOA | H12: Simple Snaive | I12: 96378 | J12: 96378 | K12: LT
A13: 3616302039357 | B13: GUCCI FL GG EDP 10 ML PENSPRAY IV | C13: P_US_ULTA | D13: Horses | E13: Weighted Snaive | F13: Weighted Snaive | G13: DES,STLF,Weighted AOA | H13: Weighted Snaive | I13: 50576 | J13: 50576 | K13: LT
A14: 3616302039548 | B14: GG PF21 EDT NS 10 ML IV | C14: P_US_ALL_OTHERS | D14: Horses | E14: Weighted Snaive | F14: TES | G14: TES,STLF,Simple Snaive | H14: Weighted Snaive | I14: 10442 | J14: 10442 | K14: ST
A15: 3616302039548 | B15: GG PF21 EDT NS 10 ML IV | C15: P_US_ULTA | D15: Horses | E15: Simple Snaive | F15: TES | G15: TES,STLF,Simple Snaive | I15: 12118 | J15: 12118 | K15: ST
A16: 3616302514298 | B16: GUCCI BM EDT NS 100 ML RG IV | C16: P_US_ALL_OTHERS | D16: Bulls | E16: Simple Snaive | F16: Simple Snaive | G16: DES,STLF,Weighted AOA,Moving Average | I16: 13457 | J16: 13457 | K16: ST
A17: 3616302514298 | B17: GUCCI BM EDT NS 100 ML RG IV | C17: P_US_ULTA | D17: Bulls | E17: TES | F17: STLF | G17: TES,STLF,Simple Snaive | I17: 14920 | J17: 14920 | K17: LT
A18: 3616302968534 | B18: GUCCI FL G JSM EDP 50 ML IV | C18: P_US_ALL_OTHERS | D18: Horses | E18: Simple Snaive | F18: TES | G18: TES,STLF,Simple Snaive | I18: 5465 | J18: 5465 | K18: ST
A19: 3616302968534 | B19: GUCCI FL G JSM EDP 50 ML IV | C19: P_US_ULTA | D19: Horses | E19: TES | G19: TES,STLF,Simple Snaive | I19: 1567 | J19: 1567 | K19: ST
A20: 3616303048198 | B20: GUCCI FL G JSM EDP 10 ML IV | C20: P_US_ALL_OTHERS | D20: Horses | E20: Weighted Snaive | F20: TES | G20: TES,STLF,Simple Snaive | H20: Weighted Snaive | I20: 24485 | J20: 24485 | K20: ST
A21: 3616303048198 | B21: GUCCI FL G JSM EDP 10 ML IV | C21: P_US_ULTA | D21: Horses | E21: STLF | F21: DES | G21: DES,STLF,Weighted AOA | H21: Weighted Snaive | I21: 3437 | J21: 3437 | K21: ST
A22: 3616303470777 | B22: GUCCI FL G MAG RG EDP 10 ML IV | C22: P_US_ALL_OTHERS | D22: Horses | E22: Weighted Snaive | F22: Weighted Snaive | G22: TES,STLF,Simple Snaive | H22: Weighted Snaive | I22: 38193 | J22: 38193 | K22: ST
A23: 3616303470777 | B23: GUCCI FL G MAG RG EDP 10 ML IV | C23: P_US_ULTA | D23: Horses | E23: STLF | F23: Weighted Snaive | G23: DES,STLF,Weighted AOA | H23: Weighted Snaive | I23: 13409 | J23: 13409 | K23: LT
A24: 3616303470791 | B24: GUCCI FL G MAG RG EDP 100 ML SCREW IV | C24: P_US_ALL_OTHERS | D24: Bulls | E24: TES | F24: STLF | G24: TES,STLF,Simple Snaive | I24: 17701 | J24: 17701 | K24: ST
A25: 3616303470791 | B25: GUCCI FL G MAG RG EDP 100 ML SCREW IV | C25: P_US_ULTA | D25: Bulls | E25: Weighted AOA | F25: STLF | G25: DES,STLF,Weighted AOA | I25: 26689 | J25: 26689 | K25: ST
A26: 3616304077005 | B26: GUCCI BM EDP 10ML PENSPRAY RG 24IV | C26: P_US_ALL_OTHERS | D26: Horses | E26: Simple Snaive | F26: STLF | G26: TES,STLF,Simple Snaive | I26: 22335 | J26: 22335 | K26: ST
A27: 3616304077005 | B27: GUCCI BM EDP 10ML PENSPRAY RG 24IV | C27: P_US_ULTA | D27: Horses | E27: Simple Snaive | F27: TES | G27: TES,STLF,Simple Snaive | I27: 14698 | J27: 14698 | K27: ST
A28: 3616304077029 | B28: GUCCI BM EDT NS 10 ML PENSPRAY RGIV | C28: P_US_ALL_OTHERS | D28: Bulls | E28: Simple Snaive | G28: TES,STLF,Simple Snaive | I28: 17582 | J28: 17582 | K28: ST
A29: 3616304077029 | B29: GUCCI BM EDT NS 10 ML PENSPRAY RGIV | C29: P_US_ULTA | D29: Bulls | E29: STLF | G29: TES,STLF,Simple Snaive | I29: 308 | J29: 308 | K29: LT
A30: 3616304175893 | B30: GG ELIXIR PH PRFM 60 ML NS IV | C30: P_US_ALL_OTHERS | D30: Horses | E30: TES | G30: TES,STLF,Simple Snaive | I30: 28589 | J30: 28589 | K30: ST
A31: 3616304175893 | B31: GG ELIXIR PH PRFM 60 ML NS IV | C31: P_US_ULTA | D31: Horses | E31: STLF | G31: TES,STLF,Simple Snaive | I31: 2726 | J31: 2726 | K31: ST
A32: 3616304175916 | B32: GG ELIXIR PF PRFM 60 ML IV | C32: P_US_ALL_OTHERS | D32: Rabbits | E32: STLF | F32: Simple Snaive | G32: TES,STLF,Simple Snaive | I32: 4991 | J32: 4991 | K32: CML
A33: 3616304175916 | B33: GG ELIXIR PF PRFM 60 ML IV | C33: P_US_ULTA | D33: Rabbits | E33: STLF | G33: TES,STLF,Simple Snaive | I33: 79 | J33: 79 | K33: LT
A34: 3616304249716 | B34: GUCCI BM EDPIN EDP 100 ML IV | C34: P_US_ALL_OTHERS | D34: Horses | E34: TES | G34: TES,STLF,Simple Snaive | I34: 11979 | J34: 11979 | K34: ST
A35: 3616304249716 | B35: GUCCI BM EDPIN EDP 100 ML IV | C35: P_US_ULTA | D35: Horses | E35: Simple Snaive | G35: TES,STLF,Simple Snaive | I35: 1945 | J35: 1945 | K35: CML
A36: 3616305169259 | B36: GUCCI FL G ORC EDP 30ML IV | C36: P_US_ALL_OTHERS | D36: Horses | E36: Simple Snaive | G36: TES,STLF,Simple Snaive | I36: 15351 | J36: 15351 | K36: LT
A37: 3616305169259 | B37: GUCCI FL G ORC EDP 30ML IV | C37: P_US_ULTA | D37: Horses | E37: DES | G37: DES,STLF,Weighted AOA | I37: 13852 | J37: 13852 | K37: LT
A38: 3616305169273 | B38: GUCCI FL G ORC EDP 100 ML VP IV | C38: P_US_ALL_OTHERS | D38: Horses | E38: STLF | F38: TES | G38: TES,STLF,Simple Snaive | I38: 17462 | J38: 17462 | K38: ST
A39: 3616305169273 | B39: GUCCI FL G ORC EDP 100 ML VP IV | C39: P_US_ULTA | D39: Horses | E39: TES | G39: TES,STLF,Simple Snaive | H39: Weighted Snaive | I39: 8421 | J39: 8421 | K39: CML
A40: 3616305169297 | B40: GUCCI FL G ORC EDP 10 ML PENSPRAY VP IV | C40: P_US_ALL_OTHERS | D40: Horses | E40: TES | F40: TES | G40: DES,STLF,Weighted AOA | H40: TES | I40: 48607 | J40: 48607 | K40: LT
...

Sheet _CALC
A1: EAN seleccionado | B1: =DASHBOARD!$C$5 | E1: Capa: System BestFit Final | F1: ="System BestFit Final"
A2: CFG seleccionado | B2: =DASHBOARD!$C$6 | E2: Capa: ST | F2: ="ST Stat Fcst"
A3: Combinado (1/0) | B3: =IF(OR($B$2="",$B$2=$B$23),1,0) | E3: Capa: LT | F3: ="LT Stat Fcst"
A4: Criterio CFG | B4: =IF($B$3=1,"*",$B$2) | E4: Capa: CML | F4: ="CML Fcst"
A5: Version actual | B5: =DASHBOARD!$C$7 | E5: Opcion algoritmo por defecto | F5: ="(ST BestFit)"
A6: Version snapshot | B6: =DASHBOARD!$C$8 | E6: Opcion sin cambio | F6: ="(SISTEMA)"
A7: Primer mes futuro | B7: =DASHBOARD!$C$9 | E7: Bucket ST | F7: ="ST"
A8: N meses detectados | B8: =COUNTIF($D$26:$AM$26,"?*") | E8: Bucket LT | F8: ="LT"
A9: N CFG del EAN | B9: =COUNTIF($B$113:$B$120,"?*") | E9: Bucket CML | F9: ="CML"
A10: CONSENSUS col Data | B10: =MATCH("Data",CONSENSUS!$1:$1,0) | E10: Pos. 1er mes futuro | F10: =IFERROR(MATCH(1,$D$30:$AM$30,0),1)
A11: CONSENSUS col EAN | B11: =MATCH("EAN",CONSENSUS!$1:$1,0) | E11: Pos. ultimo mes | F11: =MAX(1,$B$8)
A12: CONSENSUS col CFG | B12: =MATCH("CFG",CONSENSUS!$1:$1,0) | E12: Capa: System FC | F12: ="System FC - Final"
A13: CONSENSUS col Version | B13: =MATCH("Version Name",CONSENSUS!$1:$1,0) | E13: Capa: Consensus final | F13: ="Consensus - Final"
A14: BESTFIT col Data | B14: =MATCH("Data",BESTFIT!$1:$1,0) | E14: Filas halladas del EAN | F14: =COUNTIF(INDEX(CONSENSUS!$A$2:$BZ$20001,0,$B$11),$B$1)
A15: BESTFIT col Item | B15: =MATCH("ST Stat Item",BESTFIT!$1:$1,0) | E15: Capa: Consensus LY | F15: ="Consensus - Final LY M"
A16: BESTFIT col Account | B16: =MATCH("ST Stat Account",BESTFIT!$1:$1,0) | E16: Snapshot auto-detectado | F16: =IFERROR(IF(SUMPRODUCT(MIN(((INDEX(CONSENSUS!$A$2:$BZ$20001,0,$B$13)<>"")*(INDEX(CONSENSUS!$A$2:$BZ$20001,0,$B$13)<>$B$5))*(ROW(CONSENSUS!$A$2:$A$20001)-1)+(1-((INDEX(CONSENSUS!$A$2:$BZ$20001,0,$B$13)<>"")*(INDEX(CONSENSUS!$A$2:$BZ$20001,0,$B$13)<>$B$5)))*1000000))>=1000000,"",INDEX(INDEX(CONSENSUS!$A$2:$BZ$20001,0,$B$13),SUMPRODUCT(MIN(((INDEX(CONSENSUS!$A$2:$BZ$20001,0,$B$13)<>"")*(INDEX(CONSENSUS!$A$2:$BZ$20001,0,$B$13)<>$B$5))*(ROW(CONSENSUS!$A$2:$A$20001)-1)+(1-((INDEX(CONSENSUS!$A$2:$BZ$20001,0,$B$13)<>"")*(INDEX(CONSENSUS!$A$2:$BZ$20001,0,$B$13)<>$B$5)))*1000000)))),"")
A17: (libre) | E17: Primer mes futuro auto | F17: =IFERROR(TEXT(IF(VALUE(MID($B$6,13,2))=12,VALUE(MID($B$6,7,4))+1,VALUE(MID($B$6,7,4))),"0000")&".M"&TEXT(IF(VALUE(MID($B$6,13,2))=12,1,VALUE(MID($B$6,13,2))+1),"00"),$D$26)
A18: ALGO col Data | B18: =MATCH("Data",ALGO!$1:$1,0) | E18: Algoritmos activos | F18: =MAX($E$80:$E$109)
A19: ALGO col Item | B19: =MATCH("ST Stat Item",ALGO!$1:$1,0)
A20: ALGO col Account | B20: =MATCH("ST Stat Account",ALGO!$1:$1,0) | E20: House | F20: =IFERROR(INDEX(INDEX(CONSENSUS!$A$2:$BZ$20001,0,MATCH("House",CONSENSUS!$1:$1,0)),MATCH($B$1,INDEX(CONSENSUS!$A$2:$BZ$20001,0,$B$11),0)),"")
A21: ADHOC col Item | B21: =MATCH("ST Stat Item",ADHOC!$1:$1,0) | E21: Brand | F21: =IFERROR(INDEX(INDEX(CONSENSUS!$A$2:$BZ$20001,0,MATCH("Brand",CONSENSUS!$1:$1,0)),MATCH($B$1,INDEX(CONSENSUS!$A$2:$BZ$20001,0,$B$11),0)),"")
A22: ADHOC col Account | B22: =MATCH("ST Stat Account",ADHOC!$1:$1,0) | E22: Product Line | F22: =IFERROR(INDEX(INDEX(CONSENSUS!$A$2:$BZ$20001,0,MATCH("Product Line",CONSENSUS!$1:$1,0)),MATCH($B$1,INDEX(CONSENSUS!$A$2:$BZ$20001,0,$B$11),0)),"")
A23: Etiqueta "todos" | B23: ="(TODOS)" | E23: Descripcion | F23: =IFERROR(INDEX(INDEX(CONSENSUS!$A$2:$BZ$20001,0,MATCH("Planning Item Description",CONSENSUS!$1:$1,0)),MATCH($B$1,INDEX(CONSENSUS!$A$2:$BZ$20001,0,$B$11),0)),"")
A24: N interseccs. ALGO (filtro) | B24: =COUNTIFS(INDEX(ALGO!$A$2:$BZ$20001,0,$B$19),$B$1,INDEX(ALGO!$A$2:$BZ$20001,0,$B$20),$B$4,INDEX(ALGO!$A$2:$BZ$20001,0,$B$18),$B$80)
A26: Mes (cabecera fila 1) | D26: =IFERROR(IF(INDEX(CONSENSUS!$1:$1,$B$10+1)="","",INDEX(CONSENSUS!$1:$1,$B$10+1)),"") | E26: =IFERROR(IF(INDEX(CONSENSUS!$1:$1,$B$10+2)="","",INDEX(CONSENSUS!$1:$1,$B$10+2)),"") | F26: =IFERROR(IF(INDEX(CONSENSUS!$1:$1,$B$10+3)="","",INDEX(CONSENSUS!$1:$1,$B$10+3)),"") | G26: =IFERROR(IF(INDEX(CONSENSUS!$1:$1,$B$10+4)="","",INDEX(CONSENSUS!$1:$1,$B$10+4)),"") | H26: =IFERROR(IF(INDEX(CONSENSUS!$1:$1,$B$10+5)="","",INDEX(CONSENSUS!$1:$1,$B$10+5)),"") | I26: =IFERROR(IF(INDEX(CONSENSUS!$1:$1,$B$10+6)="","",INDEX(CONSENSUS!$1:$1,$B$10+6)),"") | J26: =IFERROR(IF(INDEX(CONSENSUS!$1:$1,$B$10+7)="","",INDEX(CONSENSUS!$1:$1,$B$10+7)),"") | K26: =IFERROR(IF(INDEX(CONSENSUS!$1:$1,$B$10+8)="","",INDEX(CONSENSUS!$1:$1,$B$10+8)),"") | L26: =IFERROR(IF(INDEX(CONSENSUS!$1:$1,$B$10+9)="","",INDEX(CONSENSUS!$1:$1,$B$10+9)),"") | M26: =IFERROR(IF(INDEX(CONSENSUS!$1:$1,$B$10+10)="","",INDEX(CONSENSUS!$1:$1,$B$10+10)),"") | N26: =IFERROR(IF(INDEX(CONSENSUS!$1:$1,$B$10+11)="","",INDEX(CONSENSUS!$1:$1,$B$10+11)),"") | O26: =IFERROR(IF(INDEX(CONSENSUS!$1:$1,$B$10+12)="","",INDEX(CONSENSUS!$1:$1,$B$10+12)),"") | P26: =IFERROR(IF(INDEX(CONSENSUS!$1:$1,$B$10+13)="","",INDEX(CONSENSUS!$1:$1,$B$10+13)),"") | Q26: =IFERROR(IF(INDEX(CONSENSUS!$1:$1,$B$10+14)="","",INDEX(CONSENSUS!$1:$1,$B$10+14)),"") | R26: =IFERROR(IF(INDEX(CONSENSUS!$1:$1,$B$10+15)="","",INDEX(CONSENSUS!$1:$1,$B$10+15)),"") | S26: =IFERROR(IF(INDEX(CONSENSUS!$1:$1,$B$10+16)="","",INDEX(CONSENSUS!$1:$1,$B$10+16)),"") | T26: =IFERROR(IF(INDEX(CONSENSUS!$1:$1,$B$10+17)="","",INDEX(CONSENSUS!$1:$1,$B$10+17)),"") | U26: =IFERROR(IF(INDEX(CONSENSUS!$1:$1,$B$10+18)="","",INDEX(CONSENSUS!$1:$1,$B$10+18)),"") | V26: =IFERROR(IF(INDEX(CONSENSUS!$1:$1,$B$10+19)="","",INDEX(CONSENSUS!$1:$1,$B$10+19)),"") | W26: =IFERROR(IF(INDEX(CONSENSUS!$1:$1,$B$10+20)="","",INDEX(CONSENSUS!$1:$1,$B$10+20)),"") | X26: =IFERROR(IF(INDEX(CONSENSUS!$1:$1,$B$10+21)="","",INDEX(CONSENSUS!$1:$1,$B$10+21)),"") | Y26: =IFERROR(IF(INDEX(CONSENSUS!$1:$1,$B$10+22)="","",INDEX(CONSENSUS!$1:$1,$B$10+22)),"") | Z26: =IFERROR(IF(INDEX(CONSENSUS!$1:$1,$B$10+23)="","",INDEX(CONSENSUS!$1:$1,$B$10+23)),"") | AA26: =IFERROR(IF(INDEX(CONSENSUS!$1:$1,$B$10+24)="","",INDEX(CONSENSUS!$1:$1,$B$10+24)),"") | AB26: =IFERROR(IF(INDEX(CONSENSUS!$1:$1,$B$10+25)="","",INDEX(CONSENSUS!$1:$1,$B$10+25)),"") | AC26: =IFERROR(IF(INDEX(CONSENSUS!$1:$1,$B$10+26)="","",INDEX(CONSENSUS!$1:$1,$B$10+26)),"") | AD26: =IFERROR(IF(INDEX(CONSENSUS!$1:$1,$B$10+27)="","",INDEX(CONSENSUS!$1:$1,$B$10+27)),"") | AE26: =IFERROR(IF(INDEX(CONSENSUS!$1:$1,$B$10+28)="","",INDEX(CONSENSUS!$1:$1,$B$10+28)),"") | AF26: =IFERROR(IF(INDEX(CONSENSUS!$1:$1,$B$10+29)="","",INDEX(CONSENSUS!$1:$1,$B$10+29)),"") | AG26: =IFERROR(IF(INDEX(CONSENSUS!$1:$1,$B$10+30)="","",INDEX(CONSENSUS!$1:$1,$B$10+30)),"") | AH26: =IFERROR(IF(INDEX(CONSENSUS!$1:$1,$B$10+31)="","",INDEX(CONSENSUS!$1:$1,$B$10+31)),"") | AI26: =IFERROR(IF(INDEX(CONSENSUS!$1:$1,$B$10+32)="","",INDEX(CONSENSUS!$1:$1,$B$10+32)),"") | AJ26: =IFERROR(IF(INDEX(CONSENSUS!$1:$1,$B$10+33)="","",INDEX(CONSENSUS!$1:$1,$B$10+33)),"") | AK26: =IFERROR(IF(INDEX(CONSENSUS!$1:$1,$B$10+34)="","",INDEX(CONSENSUS!$1:$1,$B$10+34)),"") | AL26: =IFERROR(IF(INDEX(CONSENSUS!$1:$1,$B$10+35)="","",INDEX(CONSENSUS!$1:$1,$B$10+35)),"") | AM26: =IFERROR(IF(INDEX(CONSENSUS!$1:$1,$B$10+36)="","",INDEX(CONSENSUS!$1:$1,$B$10+36)),"")
A27: col CONSENSUS | D27: =IF(D$26="","",$B$10+1) | E27: =IF(E$26="","",$B$10+2) | F27: =IF(F$26="","",$B$10+3) | G27: =IF(G$26="","",$B$10+4) | H27: =IF(H$26="","",$B$10+5) | I27: =IF(I$26="","",$B$10+6) | J27: =IF(J$26="","",$B$10+7) | K27: =IF(K$26="","",$B$10+8) | L27: =IF(L$26="","",$B$10+9) | M27: =IF(M$26="","",$B$10+10) | N27: =IF(N$26="","",$B$10+11) | O27: =IF(O$26="","",$B$10+12) | P27: =IF(P$26="","",$B$10+13) | Q27: =IF(Q$26="","",$B$10+14) | R27: =IF(R$26="","",$B$10+15) | S27: =IF(S$26="","",$B$10+16) | T27: =IF(T$26="","",$B$10+17) | U27: =IF(U$26="","",$B$10+18) | V27: =IF(V$26="","",$B$10+19) | W27: =IF(W$26="","",$B$10+20) | X27: =IF(X$26="","",$B$10+21) | Y27: =IF(Y$26="","",$B$10+22) | Z27: =IF(Z$26="","",$B$10+23) | AA27: =IF(AA$26="","",$B$10+24) | AB27: =IF(AB$26="","",$B$10+25) | AC27: =IF(AC$26="","",$B$10+26) | AD27: =IF(AD$26="","",$B$10+27) | AE27: =IF(AE$26="","",$B$10+28) | AF27: =IF(AF$26="","",$B$10+29) | AG27: =IF(AG$26="","",$B$10+30) | AH27: =IF(AH$26="","",$B$10+31) | AI27: =IF(AI$26="","",$B$10+32) | AJ27: =IF(AJ$26="","",$B$10+33) | AK27: =IF(AK$26="","",$B$10+34) | AL27: =IF(AL$26="","",$B$10+35) | AM27: =IF(AM$26="","",$B$10+36)
A28: col BESTFIT | D28: =IF(D$26="","",IFERROR(MATCH(D$26,BESTFIT!$1:$1,0),"")) | E28: =IF(E$26="","",IFERROR(MATCH(E$26,BESTFIT!$1:$1,0),"")) | F28: =IF(F$26="","",IFERROR(MATCH(F$26,BESTFIT!$1:$1,0),"")) | G28: =IF(G$26="","",IFERROR(MATCH(G$26,BESTFIT!$1:$1,0),"")) | H28: =IF(H$26="","",IFERROR(MATCH(H$26,BESTFIT!$1:$1,0),"")) | I28: =IF(I$26="","",IFERROR(MATCH(I$26,BESTFIT!$1:$1,0),"")) | J28: =IF(J$26="","",IFERROR(MATCH(J$26,BESTFIT!$1:$1,0),"")) | K28: =IF(K$26="","",IFERROR(MATCH(K$26,BESTFIT!$1:$1,0),"")) | ... AM28: =IF(AM$26="","",IFERROR(MATCH(AM$26,BESTFIT!$1:$1,0),""))
A29: col ALGO | D29: =IF(D$26="","",IFERROR(MATCH(D$26,ALGO!$1:$1,0),"")) | E29: =IF(E$26="","",IFERROR(MATCH(E$26,ALGO!$1:$1,0),"")) | F29: =IF(F$26="","",IFERROR(MATCH(F$26,ALGO!$1:$1,0),"")) | G29: =IF(G$26="","",IFERROR(MATCH(G$26,ALGO!$1:$1,0),"")) | H29: =IF(H$26="","",IFERROR(MATCH(H$26,ALGO!$1:$1,0),"")) | I29: =IF(I$26="","",IFERROR(MATCH(I$26,ALGO!$1:$1,0),"")) | J29: =IF(J$26="","",IFERROR(MATCH(J$26,ALGO!$1:$1,0),"")) | K29: =IF(K$26="","",IFERROR(MATCH(K$26,ALGO!$1:$1,0),"")) | ... AM29: =IF(AM$26="","",IFERROR(MATCH(AM$26,ALGO!$1:$1,0),""))
A30: futuro (1/0) | D30: =IF(D$26="","",IF(D$26>=$B$7,1,0)) | E30: =IF(E$26="","",IF(E$26>=$B$7,1,0)) | F30: =IF(F$26="","",IF(F$26>=$B$7,1,0)) | G30: =IF(G$26="","",IF(G$26>=$B$7,1,0)) | H30: =IF(H$26="","",IF(H$26>=$B$7,1,0)) | I30: =IF(I$26="","",IF(I$26>=$B$7,1,0)) | J30: =IF(J$26="","",IF(J$26>=$B$7,1,0)) | K30: =IF(K$26="","",IF(K$26>=$B$7,1,0)) | ... AM30: =IF(AM$26="","",IF(AM$26>=$B$7,1,0))
A31: Etiqueta del eje X | D31: =IF(D$26="","",IF(D$30=0,D$26&" (hist)",D$26)) | E31: =IF(E$26="","",IF(E$30=0,E$26&" (hist)",E$26)) | F31: =IF(F$26="","",IF(F$30=0,F$26&" (hist)",F$26)) | G31: =IF(G$26="","",IF(G$30=0,G$26&" (hist)",G$26)) | H31: =IF(H$26="","",IF(H$30=0,H$26&" (hist)",H$26)) | I31: =IF(I$26="","",IF(I$30=0,I$26&" (hist)",I$26)) | J31: =IF(J$26="","",IF(J$30=0,J$26&" (hist)",J$26)) | K31: =IF(K$26="","",IF(K$30=0,K$26&" (hist)",K$26)) | ... AM31: =IF(AM$26="","",IF(AM$30=0,AM$26&" (hist)",AM$26))
A33: Capa origen | B33: Etiqueta de la serie | C33: Aviso
A34: =$F$13 | B34: =$A34&" | "&$B$5 | D34: =IF(OR(D$27="",D56=0),NA(),SUMIFS(INDEX(CONSENSUS!$A$2:$BZ$20001,0,D$27),INDEX(CONSENSUS!$A$2:$BZ$20001,0,$B$11),$B$1,INDEX(CONSENSUS!$A$2:$BZ$20001,0,$B$12),$B$4,INDEX(CONSENSUS!$A$2:$BZ$20001,0,$B$13),$B$5,INDEX(CONSENSUS!$A$2:$BZ$20001,0,$B$10),$A34)) | E34: =IF(OR(E$27="",E56=0),NA(),SUMIFS(INDEX(CONSENSUS!$A$2:$BZ$20001,0,E$27),INDEX(CONSENSUS!$A$2:$BZ$20001,0,$B$11),$B$1,INDEX(CONSENSUS!$A$2:$BZ$20001,0,$B$12),$B$4,INDEX(CONSENSUS!$A$2:$BZ$20001,0,$B$13),$B$5,INDEX(CONSENSUS!$A$2:$BZ$20001,0,$B$10),$A34)) | F34: =IF(OR(F$27="",F56=0),NA(),SUMIFS(INDEX(CONSENSUS!$A$2:$BZ$20001,0,F$27),INDEX(CONSENSUS!$A$2:$BZ$20001,0,$B$11),$B$1,INDEX(CONSENSUS!$A$2:$BZ$20001,0,$B$12),$B$4,INDEX(CONSENSUS!$A$2:$BZ$20001,0,$B$13),$B$5,INDEX(CONSENSUS!$A$2:$BZ$20001,0,$B$10),$A34)) | G34: =IF(OR(G$27="",G56=0),NA(),SUMIFS(INDEX(CONSENSUS!$A$2:$BZ$20001,0,G$27),INDEX(CONSENSUS!$A$2:$BZ$20001,0,$B$11),$B$1,INDEX(CONSENSUS!$A$2:$BZ$20001,0,$B$12),$B$4,INDEX(CONSENSUS!$A$2:$BZ$20001,0,$B$13),$B$5,INDEX(CONSENSUS!$A$2:$BZ$20001,0,$B$10),$A34)) | H34: =IF(OR(H$27="",H56=0),NA(),SUMIFS(INDEX(CONSENSUS!$A$2:$BZ$20001,0,H$27),INDEX(CONSENSUS!$A$2:$BZ$20001,0,$B$11),$B$1,INDEX(CONSENSUS!$A$2:$BZ$20001,0,$B$12),$B$4,INDEX(CONSENSUS!$A$2:$BZ$20001,0,$B$13),$B$5,INDEX(CONSENSUS!$A$2:$BZ$20001,0,$B$10),$A34)) | I34: =IF(OR(I$27="",I56=0),NA(),SUMIFS(INDEX(CONSENSUS!$A$2:$BZ$20001,0,I$27),INDEX(CONSENSUS!$A$2:$BZ$20001,0,$B$11),$B$1,INDEX(CONSENSUS!$A$2:$BZ$20001,0,$B$12),$B$4,INDEX(CONSENSUS!$A$2:$BZ$20001,0,$B$13),$B$5,INDEX(CONSENSUS!$A$2:$BZ$20001,0,$B$10),$A34)) | J34: =IF(OR(J$27="",J56=0),NA(),SUMIFS(INDEX(CONSENSUS!$A$2:$BZ$20001,0,J$27),INDEX(CONSENSUS!$A$2:$BZ$20001,0,$B$11),$B$1,INDEX(CONSENSUS!$A$2:$BZ$20001,0,$B$12),$B$4,INDEX(CONSENSUS!$A$2:$BZ$20001,0,$B$13),$B$5,INDEX(CONSENSUS!$A$2:$BZ$20001,0,$B$10),$A34)) | K34: =IF(OR(K$27="",K56=0),NA(),SUMIFS(INDEX(CONSENSUS!$A$2:$BZ$20001,0,K$27),INDEX(CONSENSUS!$A$2:$BZ$20001,0,$B$11),$B$1,INDEX(CONSENSUS!$A$2:$BZ$20001,0,$B$12),$B$4,INDEX(CONSENSUS!$A$2:$BZ$20001,0,$B$13),$B$5,INDEX(CONSENSUS!$A$2:$BZ$20001,0,$B$10),$A34)) | ... AM34: =IF(OR(AM$27="",AM56=0),NA(),SUMIFS(INDEX(CONSENSUS!$A$2:$BZ$20001,0,AM$27),INDEX(CONSENSUS!$A$2:$BZ$20001,0,$B$11),$B$1,INDEX(CONSENSUS!$A$2:$BZ$20001,0,$B$12),$B$4,INDEX(CONSENSUS!$A$2:$BZ$20001,0,$B$13),$B$5,INDEX(CONSENSUS!$A$2:$BZ$20001,0,$B$10),$A34))
A35: =$F$13 | B35: =$A35&" | "&$B$6 | D35: =IF(OR(D$27="",D57=0),NA(),SUMIFS(INDEX(CONSENSUS!$A$2:$BZ$20001,0,D$27),INDEX(CONSENSUS!$A$2:$BZ$20001,0,$B$11),$B$1,INDEX(CONSENSUS!$A$2:$BZ$20001,0,$B$12),$B$4,INDEX(CONSENSUS!$A$2:$BZ$20001,0,$B$13),$B$6,INDEX(CONSENSUS!$A$2:$BZ$20001,0,$B$10),$A35)) | E35: =IF(OR(E$27="",E57=0),NA(),SUMIFS(INDEX(CONSENSUS!$A$2:$BZ$20001,0,E$27),INDEX(CONSENSUS!$A$2:$BZ$20001,0,$B$11),$B$1,INDEX(CONSENSUS!$A$2:$BZ$20001,0,$B$12),$B$4,INDEX(CONSENSUS!$A$2:$BZ$20001,0,$B$13),$B$6,INDEX(CONSENSUS!$A$2:$BZ$20001,0,$B$10),$A35)) | F35: =IF(OR(F$27="",F57=0),NA(),SUMIFS(INDEX(CONSENSUS!$A$2:$BZ$20001,0,F$27),INDEX(CONSENSUS!$A$2:$BZ$20001,0,$B$11),$B$1,INDEX(CONSENSUS!$A$2:$BZ$20001,0,$B$12),$B$4,INDEX(CONSENSUS!$A$2:$BZ$20001,0,$B$13),$B$6,INDEX(CONSENSUS!$A$2:$BZ$20001,0,$B$10),$A35)) | G35: =IF(OR(G$27="",G57=0),NA(),SUMIFS(INDEX(CONSENSUS!$A$2:$BZ$20001,0,G$27),INDEX(CONSENSUS!$A$2:$BZ$20001,0,$B$11),$B$1,INDEX(CONSENSUS!$A$2:$BZ$20001,0,$B$12),$B$4,INDEX(CONSENSUS!$A$2:$BZ$20001,0,$B$13),$B$6,INDEX(CONSENSUS!$A$2:$BZ$20001,0,$B$10),$A35)) | H35: =IF(OR(H$27="",H57=0),NA(),SUMIFS(INDEX(CONSENSUS!$A$2:$BZ$20001,0,H$27),INDEX(CONSENSUS!$A$2:$BZ$20001,0,$B$11),$B$1,INDEX(CONSENSUS!$A$2:$BZ$20001,0,$B$12),$B$4,INDEX(CONSENSUS!$A$2:$BZ$20001,0,$B$13),$B$6,INDEX(CONSENSUS!$A$2:$BZ$20001,0,$B$10),$A35)) | I35: =IF(OR(I$27="",I57=0),NA(),SUMIFS(INDEX(CONSENSUS!$A$2:$BZ$20001,0,I$27),INDEX(CONSENSUS!$A$2:$BZ$20001,0,$B$11),$B$1,INDEX(CONSENSUS!$A$2:$BZ$20001,0,$B$12),$B$4,INDEX(CONSENSUS!$A$2:$BZ$20001,0,$B$13),$B$6,INDEX(CONSENSUS!$A$2:$BZ$20001,0,$B$10),$A35)) | J35: =IF(OR(J$27="",J57=0),NA(),SUMIFS(INDEX(CONSENSUS!$A$2:$BZ$20001,0,J$27),INDEX(CONSENSUS!$A$2:$BZ$20001,0,$B$11),$B$1,INDEX(CONSENSUS!$A$2:$BZ$20001,0,$B$12),$B$4,INDEX(CONSENSUS!$A$2:$BZ$20001,0,$B$13),$B$6,INDEX(CONSENSUS!$A$2:$BZ$20001,0,$B$10),$A35)) | K35: =IF(OR(K$27="",K57=0),NA(),SUMIFS(INDEX(CONSENSUS!$A$2:$BZ$20001,0,K$27),INDEX(CONSENSUS!$A$2:$BZ$20001,0,$B$11),$B$1,INDEX(CONSENSUS!$A$2:$BZ$20001,0,$B$12),$B$4,INDEX(CONSENSUS!$A$2:$BZ$20001,0,$B$13),$B$6,INDEX(CONSENSUS!$A$2:$BZ$20001,0,$B$10),$A35)) | ... AM35: =IF(OR(AM$27="",AM57=0),NA(),SUMIFS(INDEX(CONSENSUS!$A$2:$BZ$20001,0,AM$27),INDEX(CONSENSUS!$A$2:$BZ$20001,0,$B$11),$B$1,INDEX(CONSENSUS!$A$2:$BZ$20001,0,$B$12),$B$4,INDEX(CONSENSUS!$A$2:$BZ$20001,0,$B$13),$B$6,INDEX(CONSENSUS!$A$2:$BZ$20001,0,$B$10),$A35))
